<?xml version="1.0"?>
<testsuites>
  <testsuite name="default" tests="0"/>
  <testsuite name="GitHub" tests="7" failures="2" skipped="0" errors="0" time="17.678">
    <testcase name="Successfully create 3 distinct repositories and assert that the response code is correct Line #11" time="2.909" status="passed"/>
    <testcase name="Successfully create 3 distinct repositories and assert that the response code is correct Line #12" time="2.19" status="passed"/>
    <testcase name="Successfully create 3 distinct repositories and assert that the response code is correct Line #13" time="1.698" status="passed"/>
    <testcase name="Delete successfully one of them and assert that the response code is correct" time="3.361" status="passed"/>
    <testcase name="Try to delete again one of the repositories and assert that the response code is correct for a failed delete" time="2.065" status="passed"/>
    <testcase name="List the remaining repositories and assert the response code is correct, assert that the 2&#10;remaining repositories are still present and also assert that the deleted repository is&#10;present(this assert should fail)" time="1.644" status="failed">
      <failure type="Exception"><![CDATA[And "Repo1" repository is present:

The expected repo: Repo1 is not present]]></failure>
    </testcase>
    <testcase name="Delete all repositories" time="3.574" status="failed">
      <failure type="Behat\Testwork\Call\Exception\FatalThrowableError"><![CDATA[When I call the "https://api.github.com/repos" api method to delete all repos:

Fatal error: Call to undefined method Asserts\Asserts::assertRepoIsDeleted()]]></failure>
    </testcase>
  </testsuite>
</testsuites>
